<?xml version='1.0' encoding='utf-8'?>
<robot name="rc5_aero_hand">
  <link name="world" />
  <link name="body0">
    <visual>
      <origin xyz="0 0 0" rpy="0 0 0" />
      <geometry>
        <mesh filename="meshes/Unnamed2_Base_RC_5.dae" />
      </geometry>
      <material name="black">
        <color rgba="0 0 0 1" />
      </material>
    </visual>
    <collision>
      <origin xyz="0 0 0.075" rpy="0 0 0" />
      <geometry>
        <box size="0.15 0.15 0.15" />
      </geometry>
    </collision>
    <inertial>
      <origin xyz="0 0 0.075" rpy="0 0 0" />
      <mass value="1.0" />
      <inertia ixx="0.001" ixy="0.0" ixz="0.0" iyy="0.001" iyz="0.0" izz="0.001" />
    </inertial>
  </link>
  <link name="body1">
    <visual>
      <origin xyz="0 -0.1725 0 " rpy="-1.5708 0 0" />
      <geometry>
        <mesh filename="./meshes/Unnamed2_1_RC_5.dae" />
      </geometry>
      <material name="black">
        <color rgba="0 0 0 1" />
      </material>
    </visual>
    <collision>
      <origin xyz="0.0 0.0 0.09" rpy="0 0 0" />
      <geometry>
        <box size="0.03 0.03 0.03" />
      </geometry>
    </collision>
    <inertial>
      <origin xyz="-0.00019409 -0.02779038 0.00595929" rpy="0 0 0" />
      <mass value="4.82600479" />
      <inertia ixx="0.01070724" ixy="-0.00006759" ixz="-0.00000871" iyy="0.00907537" iyz="0.00081924" izz="0.00996983" />
    </inertial>
  </link>
  <link name="body2">
    <visual>
      <origin xyz="0.1725 0.0 -0.156" rpy="-1.5708 0 1.5708" />
      <geometry>
        <mesh filename="./meshes/Unnamed2_2_RC_5.dae" />
      </geometry>
      <material name="black">
        <color rgba="0 0 0 1" />
      </material>
    </visual>
    <collision>
      <origin xyz="-0.27 0.0 0" rpy="0 0 0" />
      <geometry>
        <box size="0.32 0.1 0.1" />
      </geometry>
    </collision>
    <inertial>
      <origin xyz="0.20250821 0.00001798 -0.02413996" rpy="0 0 0" />
      <mass value="11.10382927" />
      <inertia ixx="0.02403053" ixy="0.00035076" ixz="0.00000220" iyy="0.41007610" iyz="0.00000531" izz="0.40581383" />
    </inertial>
  </link>
  <link name="body3">
    <visual>
      <origin xyz="0.577  0.0 0" rpy="-1.5708 0 1.5708" />
      <geometry>
        <mesh filename="./meshes/Unnamed2_3_RC_5.dae" />
      </geometry>
      <material name="black">
        <color rgba="0 0 0 1" />
      </material>
    </visual>
    <collision>
      <origin xyz="-0.18 0.0 0.0" rpy="0 0 0" />
      <geometry>
        <box size="0.45 0.1 0.1" />
      </geometry>
    </collision>
    <inertial>
      <origin xyz="0.13039638 0.00011948 0.02366635" rpy="0 0 0" />
      <mass value="4.57367289" />
      <inertia ixx="0.00825994" ixy="-0.00004403" ixz="-0.00475038" iyy="0.11580371" iyz="-0.00001780" izz="0.11358420" />
    </inertial>
  </link>
  <link name="body4">
    <visual>
      <origin xyz="0 -0.147 -0.95 " rpy="0 0 3.1415" />
      <geometry>
        <mesh filename="./meshes/Unnamed2_4_RC_5.dae" />
      </geometry>
      <material name="black">
        <color rgba="0 0 0 1" />
      </material>
    </visual>
    <collision>
      <origin xyz="0.0 0.0 0.0" rpy="0 0 0" />
      <geometry>
        <box size="0.1 0.1 0.1" />
      </geometry>
    </collision>
    <inertial>
      <origin xyz="0.00017970 -0.00433297 0.03407774" rpy="0 0 0" />
      <mass value="2.44096949" />
      <inertia ixx="0.00416357" ixy="-0.00000442" ixz="-0.00002537" iyy="0.00394647" iyz="0.00037030" izz="0.00252766" />
    </inertial>
  </link>
  <link name="body5">
    <visual>
      <origin xyz="0.000 1.09 -0.147" rpy="1.5708 3.1415 0" />
      <geometry>
        <mesh filename="./meshes/Unnamed2_5_RC_5.dae" />
      </geometry>
      <material name="black">
        <color rgba="0 0 0 1" />
      </material>
    </visual>
    <collision>
      <origin xyz="0.0 0.0 0.0" rpy="0 0 0" />
      <geometry>
        <box size="0.1 0.1 0.1" />
      </geometry>
    </collision>
    <inertial>
      <origin xyz="-0.00015337 0.00433297 0.03410407" rpy="0 0 0" />
      <mass value="2.44096949" />
      <inertia ixx="0.00416402" ixy="-0.00000129" ixz="0.00002319" iyy="0.00394211" iyz="-0.00036717" izz="0.00252285" />
    </inertial>
  </link>
  <link name="body6">
    <visual>
      <origin xyz="0 -1.09 -0.3" rpy="-1.5708 0 0" />
      <geometry>
        <mesh filename="./meshes/Unnamed2_6_RC_5.dae" />
      </geometry>
      <material name="black">
        <color rgba="0 0 0 1" />
      </material>
    </visual>
    <collision>
      <origin xyz="0.0 0.0 -0.03" rpy="0 0 0" />
      <geometry>
        <box size="0.1 0.1 0.1" />
      </geometry>
    </collision>
    <inertial>
      <origin xyz="0.00000000 -0.00098373 -0.02806058" rpy="0 0 0" />
      <mass value="0.51167316" />
      <inertia ixx="0.00047072" ixy="0.00000000" ixz="0.00000000" iyy="0.00048361" iyz="0.00000197" izz="0.00064554" />
    </inertial>
  </link>
  <link name="frame1" />
  <link name="frame2" />
  <link name="frame2_1" />
  <link name="frame3" />
  <link name="frame3_1" />
  <link name="frame4" />
  <link name="frame5" />
  <link name="frame6" />
  <joint name="fixed0" type="fixed">
    <parent link="world" />
    <child link="body0" />
  </joint>
  <joint name="joint0" type="revolute">
    <parent link="body0" />
    <child link="frame1" />
    <axis xyz="0 0 1" />
    <limit lower="-3.14" upper="3.14" effort="100" velocity="2.0" />
  </joint>
  <joint name="fixed1" type="fixed">
    <parent link="frame1" />
    <child link="body1" />
    <origin xyz="0 0 0.1725" rpy="1.5708 0 1.569203673" />
  </joint>
  <joint name="joint1" type="revolute">
    <parent link="body1" />
    <child link="frame2" />
    <axis xyz="0 0 1" />
    <limit lower="-3.14" upper="3.14" effort="100" velocity="2.0" />
  </joint>
  <joint name="fixed2" type="fixed">
    <parent link="frame2" />
    <child link="body2" />
    <origin xyz="0 0 0.156" rpy="0 0 0.000095102" />
  </joint>
  <joint name="fixed2_1" type="fixed">
    <parent link="body2" />
    <child link="frame2_1" />
    <origin xyz="-0.405 0 0" rpy="0 0 2.0943" />
  </joint>
  <joint name="joint2" type="revolute">
    <parent link="frame2_1" />
    <child link="frame3" />
    <axis xyz="0 0 1" />
    <limit lower="-2.91469985083053" upper="2.91469985083053" effort="100" velocity="2.0" />
  </joint>
  <joint name="fixed3" type="fixed">
    <parent link="frame3" />
    <child link="body3" />
    <origin xyz="0 0 -0.1485" rpy="0 0 -2.094395102" />
  </joint>
  <joint name="fixed3_1" type="fixed">
    <parent link="body3" />
    <child link="frame3_1" />
    <origin xyz="-0.3722 0 0" rpy="0 0 0" />
  </joint>
  <joint name="joint3" type="revolute">
    <parent link="frame3_1" />
    <child link="frame4" />
    <axis xyz="0 0 1" />
    <limit lower="-3.14" upper="3.14" effort="50" velocity="1.5" />
  </joint>
  <joint name="fixed4" type="fixed">
    <parent link="frame4" />
    <child link="body4" />
    <origin xyz="0 0 0.1398" rpy="1.5708 0 0.000003673" />
  </joint>
  <joint name="joint4" type="revolute">
    <parent link="body4" />
    <child link="frame5" />
    <axis xyz="0 0 1" />
    <limit lower="-3.14" upper="3.14" effort="50" velocity="1.5" />
  </joint>
  <joint name="fixed5" type="fixed">
    <parent link="frame5" />
    <child link="body5" />
    <origin xyz="0 0 0.1398" rpy="1.5708 3.14 3.140796327" />
  </joint>
  <joint name="joint5" type="revolute">
    <parent link="body5" />
    <child link="frame6" />
    <axis xyz="0 0 1" />
    <limit lower="-3.14" upper="3.14" effort="30" velocity="1.0" />
  </joint>
  <joint name="fixed6" type="fixed">
    <parent link="frame6" />
    <child link="body6" />
    <origin xyz="0 0 0.1398" rpy="0 0 3.1415" />
  </joint>
  <joint name="gripper_mount" type="fixed">
    <parent link="body6" />
    <child link="prehand_cam" />
    <origin xyz="0 0 0.0885" rpy="0 3.1415 0" />
  </joint>
  <link name="prehand_cam">
    <inertial>
      <origin xyz="0.00109122507694746 0.00334946623951281 0.0489855934276007" rpy="0 0 0" />
      <mass value="0.03" />
      <inertia ixx="0.001" ixy="0.0" ixz="0.0" iyy="0.001" iyz="0.0" izz="0.001" />
    </inertial>
    <visual>
      <origin xyz="0 0 0" rpy="0 0 0" />
      <geometry>
        <mesh filename="./prehand_meshes/prehand_cam.dae" scale="0.001 0.001 0.001" />
      </geometry>
      <material name="green">
        <color rgba="0 1 0 1" />
      </material>
    </visual>
    <collision>
      <origin xyz="0 0 0" rpy="0 0 0" />
      <geometry>
        <mesh filename="./prehand_meshes/prehand_cam.dae" scale="0.001 0.001 0.001" />
      </geometry>
    </collision>
  </link>
  <joint name="gripper_mount2" type="fixed">
    <parent link="prehand_cam" />
    <child link="right_base_link" />
    <origin xyz="0 0 0" rpy="0 3.1415 3.1415" />
  </joint>
  <link name="right_base_link">
    <inertial>
      <origin xyz="0.00109122507694746 0.00334946623951281 0.0489855934276007" rpy="0 0 0" />
      <mass value="0.303576106034272" />
      <inertia ixx="0.0003204846476097" ixy="2.62190795371995E-06" ixz="1.78273132959694E-05" iyy="0.000498321260315036" iyz="-1.89908549049557E-05" izz="0.000236845827410211" />
    </inertial>
    <visual>
      <origin xyz="0 0 0" rpy="0 0 0" />
      <geometry>
        <mesh filename="./aero_hand_meshes/right_base_link.STL" />
      </geometry>
      <material name="aero_hand_gray">
        <color rgba="0.7 0.7 0.7 1" />
      </material>
    </visual>
    <collision>
      <origin xyz="0 0 0" rpy="0 0 0" />
      <geometry>
        <mesh filename="./aero_hand_meshes/right_base_link.STL" />
      </geometry>
    </collision>
  </link>
  <joint name="right_tcp_mount" type="fixed">
    <parent link="right_base_link" />
    <child link="right_tcp_link" />
    <origin xyz="0 0 0.065" rpy="0 0 0" />
  </joint>
  <link name="right_tcp_link">
    <inertial>
      <origin xyz="0 0 0" rpy="0 0 0" />
      <mass value="0.0001" />
      <inertia ixx="1e-08" ixy="0.0" ixz="0.0" iyy="1e-08" iyz="0.0" izz="1e-08" />
    </inertial>
  </link>
  <link name="right_t_link">
    <inertial>
      <origin xyz="-0.000883525104759189 0.00170407980029484 0.00831028240403424" rpy="0 0 0" />
      <mass value="0.00833536405562315" />
      <inertia ixx="8.98196341850234E-07" ixy="5.06324261689494E-08" ixz="7.80847786775035E-08" iyy="6.56600038000196E-07" iyz="-1.15246746917096E-07" izz="4.94642305198558E-07" />
    </inertial>
    <visual>
      <origin xyz="0 0 0" rpy="0 0 0" />
      <geometry>
        <mesh filename="./aero_hand_meshes/right_t_link.STL" />
      </geometry>
      <material name="aero_hand_gray">
        <color rgba="0.7 0.7 0.7 1" />
      </material>
    </visual>
    <collision>
      <origin xyz="0 0 0" rpy="0 0 0" />
      <geometry>
        <mesh filename="./aero_hand_meshes/right_t_link.STL" />
      </geometry>
    </collision>
  </link>
  <joint name="right_thumb_cmc_abd" type="revolute">
    <origin xyz="0.028112 -0.0145 0.025363" rpy="-1.2217 -0.0 -1.57" />
    <parent link="right_base_link" />
    <child link="right_t_link" />
    <axis xyz="0 1 0" />
    <limit lower="0" upper="1.7453" effort="0" velocity="0" />
  </joint>
  <link name="right_thumb_mcp_link">
    <inertial>
      <origin xyz="-1.9848E-07 0.00075445 0.014668" rpy="0 0 0" />
      <mass value="0.008207" />
      <inertia ixx="1.1501E-06" ixy="1.5891E-11" ixz="-2.1442E-11" iyy="1.2374E-06" iyz="2.9444E-08" izz="5.8804E-07" />
    </inertial>
    <visual>
      <origin xyz="0 0 0" rpy="0 0 0" />
      <geometry>
        <mesh filename="./aero_hand_meshes/right_thumb_mcp_link.STL" />
      </geometry>
      <material name="aero_hand_gray">
        <color rgba="0.7 0.7 0.7 1" />
      </material>
    </visual>
    <collision>
      <origin xyz="0 0 0" rpy="0 0 0" />
      <geometry>
        <mesh filename="./aero_hand_meshes/right_thumb_mcp_link.STL" />
      </geometry>
    </collision>
  </link>
  <joint name="right_thumb_cmc_flex" type="revolute">
    <origin xyz="-0.003475 0.003808 0.019656" rpy="0.1325 -0.17906 0.26195" />
    <parent link="right_t_link" />
    <child link="right_thumb_mcp_link" />
    <axis xyz="1 0 0" />
    <limit lower="0" upper="0.9599" effort="0" velocity="0" />
  </joint>
  <link name="right_thumb_proximal_link">
    <inertial>
      <origin xyz="7.9121E-09 0.001007 0.011955" rpy="0 0 0" />
      <mass value="0.005471" />
      <inertia ixx="5.6266E-07" ixy="-1.2619E-11" ixz="4.6488E-12" iyy="6.6259E-07" iyz="1.0326E-08" izz="3.2352E-07" />
    </inertial>
    <visual>
      <origin xyz="0 0 0" rpy="0 0 0" />
      <geometry>
        <mesh filename="./aero_hand_meshes/right_thumb_proximal_link.STL" />
      </geometry>
      <material name="aero_hand_gray">
        <color rgba="0.7 0.7 0.7 1" />
      </material>
    </visual>
    <collision>
      <origin xyz="0 0 0" rpy="0 0 0" />
      <geometry>
        <mesh filename="./aero_hand_meshes/right_thumb_proximal_link.STL" />
      </geometry>
    </collision>
  </link>
  <joint name="right_thumb_mcp" type="revolute">
    <origin xyz="0 0.0033822 0.035848" rpy="0 0 0" />
    <parent link="right_thumb_mcp_link" />
    <child link="right_thumb_proximal_link" />
    <axis xyz="1 0 0" />
    <limit lower="0" upper="1.5708" effort="0" velocity="0" />
  </joint>
  <link name="right_thumb_distal_link">
    <inertial>
      <origin xyz="-6.4155E-07 -0.0011983 0.010377" rpy="0 0 0" />
      <mass value="0.0032396" />
      <inertia ixx="2.7433E-07" ixy="3.5329E-12" ixz="1.7025E-11" iyy="2.5791E-07" iyz="-5.5405E-08" izz="1.196E-07" />
    </inertial>
    <visual>
      <origin xyz="0 0 0" rpy="0 0 0" />
      <geometry>
        <mesh filename="./aero_hand_meshes/right_thumb_distal_link.STL" />
      </geometry>
      <material name="aero_hand_gray">
        <color rgba="0.7 0.7 0.7 1" />
      </material>
    </visual>
    <collision>
      <origin xyz="0 0 0" rpy="0 0 0" />
      <geometry>
        <mesh filename="./aero_hand_meshes/right_thumb_distal_link.STL" />
      </geometry>
    </collision>
    <visual>
      <origin xyz="0 0.0059474 0.031823" rpy="0 0 0" />
      <geometry>
        <mesh filename="./aero_hand_meshes/right_thumb_tip_link.STL" />
      </geometry>
      <material name="aero_hand_gray">
        <color rgba="0.7 0.7 0.7 1" />
      </material>
    </visual>
    <collision>
      <origin xyz="0 0.0059474 0.031823" rpy="0 0 0" />
      <geometry>
        <mesh filename="./aero_hand_meshes/right_thumb_tip_link.STL" />
      </geometry>
    </collision>
  </link>
  <joint name="right_thumb_ip" type="revolute">
    <origin xyz="0 0.002206 0.029919" rpy="0 0 0" />
    <parent link="right_thumb_proximal_link" />
    <child link="right_thumb_distal_link" />
    <axis xyz="1 0 0" />
    <limit lower="0" upper="1.5708" effort="0" velocity="0" />
  </joint>
  <link name="right_index_proximal_link">
    <inertial>
      <origin xyz="4.30529992941076E-08 -0.0024559603959039 0.0191142514901699" rpy="0 0 0" />
      <mass value="0.00720026836301954" />
      <inertia ixx="1.11576979742814E-06" ixy="-2.42664231429577E-12" ixz="-8.53111702205322E-12" iyy="1.1011227010753E-06" iyz="1.07385658133945E-07" izz="2.80496727013047E-07" />
    </inertial>
    <visual>
      <origin xyz="0 0 0" rpy="0 0 0" />
      <geometry>
        <mesh filename="./aero_hand_meshes/right_index_proximal_link.STL" />
      </geometry>
      <material name="aero_hand_gray">
        <color rgba="0.7 0.7 0.7 1" />
      </material>
    </visual>
    <collision>
      <origin xyz="0 0 0" rpy="0 0 0" />
      <geometry>
        <mesh filename="./aero_hand_meshes/right_index_proximal_link.STL" />
      </geometry>
    </collision>
  </link>
  <joint name="right_index_mcp_flex" type="revolute">
    <origin xyz="0.030626 -0.0011782 0.10542" rpy="0 0.05236 -0.034907" />
    <parent link="right_base_link" />
    <child link="right_index_proximal_link" />
    <axis xyz="1 0 0" />
    <limit lower="0" upper="1.5708" effort="0" velocity="0" />
  </joint>
  <link name="right_index_middle_link">
    <inertial>
      <origin xyz="-6.47985752902369E-09 -0.000363269614703799 0.00876079008757696" rpy="0 0 0" />
      <mass value="0.00276150356687874" />
      <inertia ixx="1.80416885776444E-07" ixy="1.11705685747945E-13" ixz="-3.17914278530766E-14" iyy="1.9897239153381E-07" iyz="7.6558277494112E-09" izz="8.93351684671892E-08" />
    </inertial>
    <visual>
      <origin xyz="0 0 0" rpy="0 0 0" />
      <geometry>
        <mesh filename="./aero_hand_meshes/right_index_middle_link.STL" />
      </geometry>
      <material name="aero_hand_gray">
        <color rgba="0.7 0.7 0.7 1" />
      </material>
    </visual>
    <collision>
      <origin xyz="0 0 0" rpy="0 0 0" />
      <geometry>
        <mesh filename="./aero_hand_meshes/right_index_middle_link.STL" />
      </geometry>
    </collision>
  </link>
  <joint name="right_index_pip" type="revolute">
    <origin xyz="0 -0.0014554 0.043" rpy="0 0 0" />
    <parent link="right_index_proximal_link" />
    <child link="right_index_middle_link" />
    <axis xyz="1 0 0" />
    <limit lower="0" upper="1.5708" effort="0" velocity="0" />
  </joint>
  <link name="right_index_distal_link">
    <inertial>
      <origin xyz="3.34671961321059E-07 -0.00120224143694181 0.00777234707760652" rpy="0 0 0" />
      <mass value="0.00183663667769987" />
      <inertia ixx="1.0824117936487E-07" ixy="2.22622444751556E-12" ixz="4.51561065548065E-13" iyy="1.0024267178837E-07" iyz="-1.85905628716286E-08" izz="3.57211667407306E-08" />
    </inertial>
    <visual>
      <origin xyz="0 0 0" rpy="0 0 0" />
      <geometry>
        <mesh filename="./aero_hand_meshes/right_index_distal_link.STL" />
      </geometry>
      <material name="aero_hand_gray">
        <color rgba="0.7 0.7 0.7 1" />
      </material>
    </visual>
    <collision>
      <origin xyz="0 0 0" rpy="0 0 0" />
      <geometry>
        <mesh filename="./aero_hand_meshes/right_index_distal_link.STL" />
      </geometry>
    </collision>
    <visual>
      <origin xyz="0 0.003512 0.026776" rpy="0 0 0" />
      <geometry>
        <mesh filename="./aero_hand_meshes/right_index_tip_link.STL" />
      </geometry>
      <material name="aero_hand_gray">
        <color rgba="0.7 0.7 0.7 1" />
      </material>
    </visual>
    <collision>
      <origin xyz="0 0.003512 0.026776" rpy="0 0 0" />
      <geometry>
        <mesh filename="./aero_hand_meshes/right_index_tip_link.STL" />
      </geometry>
    </collision>
  </link>
  <joint name="right_index_dip" type="revolute">
    <origin xyz="0 0 0.022" rpy="0 0 0" />
    <parent link="right_index_middle_link" />
    <child link="right_index_distal_link" />
    <axis xyz="1 0 0" />
    <limit lower="0" upper="1.5708" effort="0" velocity="0" />
  </joint>
  <link name="right_middle_proximal_link">
    <inertial>
      <origin xyz="3.04863738940235E-08 -0.00245596411252013 0.0191142544123753" rpy="0 0 0" />
      <mass value="0.0072002618370038" />
      <inertia ixx="1.11576923655936E-06" ixy="-2.87314711925059E-12" ixz="-7.93183989281095E-12" iyy="1.10112189499846E-06" iyz="1.07384680629995E-07" izz="2.80496366633981E-07" />
    </inertial>
    <visual>
      <origin xyz="0 0 0" rpy="0 0 0" />
      <geometry>
        <mesh filename="./aero_hand_meshes/right_middle_proximal_link.STL" />
      </geometry>
      <material name="aero_hand_gray">
        <color rgba="0.7 0.7 0.7 1" />
      </material>
    </visual>
    <collision>
      <origin xyz="0 0 0" rpy="0 0 0" />
      <geometry>
        <mesh filename="./aero_hand_meshes/right_middle_proximal_link.STL" />
      </geometry>
    </collision>
  </link>
  <joint name="right_middle_mcp_flex" type="revolute">
    <origin xyz="0.0075 0 0.106" rpy="0 0 0" />
    <parent link="right_base_link" />
    <child link="right_middle_proximal_link" />
    <axis xyz="1 0 0" />
    <limit lower="0" upper="1.5708" effort="0" velocity="0" />
  </joint>
  <link name="right_middle_middle_link">
    <inertial>
      <origin xyz="-2.85973601964011E-09 -0.000363264332488778 0.00876078146450842" rpy="0 0 0" />
      <mass value="0.00276150069139886" />
      <inertia ixx="1.80416617173586E-07" ixy="1.53011003427557E-13" ixz="-1.41103664305574E-13" iyy="1.9897228701034E-07" iyz="7.6556903630071E-09" izz="8.9334989431654E-08" />
    </inertial>
    <visual>
      <origin xyz="0 0 0" rpy="0 0 0" />
      <geometry>
        <mesh filename="./aero_hand_meshes/right_middle_middle_link.STL" />
      </geometry>
      <material name="aero_hand_gray">
        <color rgba="0.7 0.7 0.7 1" />
      </material>
    </visual>
    <collision>
      <origin xyz="0 0 0" rpy="0 0 0" />
      <geometry>
        <mesh filename="./aero_hand_meshes/right_middle_middle_link.STL" />
      </geometry>
    </collision>
  </link>
  <joint name="right_middle_pip" type="revolute">
    <origin xyz="0 -0.0014554 0.043" rpy="0 0 0" />
    <parent link="right_middle_proximal_link" />
    <child link="right_middle_middle_link" />
    <axis xyz="1 0 0" />
    <limit lower="0" upper="1.5708" effort="0" velocity="0" />
  </joint>
  <link name="right_middle_distal_link">
    <inertial>
      <origin xyz="1.25205983373364E-07 -0.00120223641223895 0.00777324919661349" rpy="0 0 0" />
      <mass value="0.00183690507488675" />
      <inertia ixx="1.08253108089546E-07" ixy="2.19334961795908E-12" ixz="2.52507113254221E-12" iyy="1.00254686909563E-07" iyz="-1.85902271227329E-08" izz="3.57231402201655E-08" />
    </inertial>
    <visual>
      <origin xyz="0 0 0" rpy="0 0 0" />
      <geometry>
        <mesh filename="./aero_hand_meshes/right_middle_distal_link.STL" />
      </geometry>
      <material name="aero_hand_gray">
        <color rgba="0.7 0.7 0.7 1" />
      </material>
    </visual>
    <collision>
      <origin xyz="0 0 0" rpy="0 0 0" />
      <geometry>
        <mesh filename="./aero_hand_meshes/right_middle_distal_link.STL" />
      </geometry>
    </collision>
    <visual>
      <origin xyz="0 0.003512 0.026776" rpy="0 0 0" />
      <geometry>
        <mesh filename="./aero_hand_meshes/right_middle_tip_link.STL" />
      </geometry>
      <material name="aero_hand_gray">
        <color rgba="0.7 0.7 0.7 1" />
      </material>
    </visual>
    <collision>
      <origin xyz="0 0.003512 0.026776" rpy="0 0 0" />
      <geometry>
        <mesh filename="./aero_hand_meshes/right_middle_tip_link.STL" />
      </geometry>
    </collision>
  </link>
  <joint name="right_middle_dip" type="revolute">
    <origin xyz="0 0 0.022" rpy="0 0 0" />
    <parent link="right_middle_middle_link" />
    <child link="right_middle_distal_link" />
    <axis xyz="1 0 0" />
    <limit lower="0" upper="1.5708" effort="0" velocity="0" />
  </joint>
  <link name="right_ring_proximal_link">
    <inertial>
      <origin xyz="-2.24219388229863E-08 -0.00245596869794189 0.0191142172606163" rpy="0 0 0" />
      <mass value="0.00720026581090036" />
      <inertia ixx="1.11577050567807E-06" ixy="5.89521141957177E-14" ixz="1.83895388831523E-12" iyy="1.10112290329168E-06" iyz="1.07384543663671E-07" izz="2.8049685394292E-07" />
    </inertial>
    <visual>
      <origin xyz="0 0 0" rpy="0 0 0" />
      <geometry>
        <mesh filename="./aero_hand_meshes/right_ring_proximal_link.STL" />
      </geometry>
      <material name="aero_hand_gray">
        <color rgba="0.7 0.7 0.7 1" />
      </material>
    </visual>
    <collision>
      <origin xyz="0 0 0" rpy="0 0 0" />
      <geometry>
        <mesh filename="./aero_hand_meshes/right_ring_proximal_link.STL" />
      </geometry>
    </collision>
  </link>
  <joint name="right_ring_mcp_flex" type="revolute">
    <origin xyz="-0.015626 -0.0011782 0.10542" rpy="0 -0.05236 0.034907" />
    <parent link="right_base_link" />
    <child link="right_ring_proximal_link" />
    <axis xyz="1 0 0" />
    <limit lower="0" upper="1.5708" effort="0" velocity="0" />
  </joint>
  <link name="right_ring_middle_link">
    <inertial>
      <origin xyz="-1.05768104170789E-08 -0.000363267692106015 0.00876078358138278" rpy="0 0 0" />
      <mass value="0.00276150640462905" />
      <inertia ixx="1.80417110518944E-07" ixy="2.51240159687594E-13" ixz="-1.96663252625615E-13" iyy="1.98972658288888E-07" iyz="7.65587908401087E-09" izz="8.93352335930394E-08" />
    </inertial>
    <visual>
      <origin xyz="0 0 0" rpy="0 0 0" />
      <geometry>
        <mesh filename="./aero_hand_meshes/right_ring_middle_link.STL" />
      </geometry>
      <material name="aero_hand_gray">
        <color rgba="0.7 0.7 0.7 1" />
      </material>
    </visual>
    <collision>
      <origin xyz="0 0 0" rpy="0 0 0" />
      <geometry>
        <mesh filename="./aero_hand_meshes/right_ring_middle_link.STL" />
      </geometry>
    </collision>
  </link>
  <joint name="right_ring_pip" type="revolute">
    <origin xyz="0 -0.0014554 0.043" rpy="0 0 0" />
    <parent link="right_ring_proximal_link" />
    <child link="right_ring_middle_link" />
    <axis xyz="1 0 0" />
    <limit lower="0" upper="1.5708" effort="0" velocity="0" />
  </joint>
  <link name="right_ring_distal_link">
    <inertial>
      <origin xyz="4.41236248528015E-07 -0.00120206116795719 0.0077717480697731" rpy="0 0 0" />
      <mass value="0.00183637337497735" />
      <inertia ixx="1.08230484308911E-07" ixy="3.2022518221628E-12" ixz="1.46160641586203E-14" iyy="1.00234337412801E-07" iyz="-1.85889383348734E-08" izz="3.57187511592097E-08" />
    </inertial>
    <visual>
      <origin xyz="0 0 0" rpy="0 0 0" />
      <geometry>
        <mesh filename="./aero_hand_meshes/right_ring_distal_link.STL" />
      </geometry>
      <material name="aero_hand_gray">
        <color rgba="0.7 0.7 0.7 1" />
      </material>
    </visual>
    <collision>
      <origin xyz="0 0 0" rpy="0 0 0" />
      <geometry>
        <mesh filename="./aero_hand_meshes/right_ring_distal_link.STL" />
      </geometry>
    </collision>
    <visual>
      <origin xyz="0 0.003512 0.026776" rpy="0 0 0" />
      <geometry>
        <mesh filename="./aero_hand_meshes/right_ring_tip_link.STL" />
      </geometry>
      <material name="aero_hand_gray">
        <color rgba="0.7 0.7 0.7 1" />
      </material>
    </visual>
    <collision>
      <origin xyz="0 0.003512 0.026776" rpy="0 0 0" />
      <geometry>
        <mesh filename="./aero_hand_meshes/right_ring_tip_link.STL" />
      </geometry>
    </collision>
  </link>
  <joint name="right_ring_dip" type="revolute">
    <origin xyz="0 0 0.022" rpy="0 0 0" />
    <parent link="right_ring_middle_link" />
    <child link="right_ring_distal_link" />
    <axis xyz="1 0 0" />
    <limit lower="0" upper="1.5708" effort="0" velocity="0" />
  </joint>
  <link name="right_pinky_proximal_link">
    <inertial>
      <origin xyz="-2.95727574026183E-08 -0.00245597557732571 0.0191142201685638" rpy="0 0 0" />
      <mass value="0.00720026164932404" />
      <inertia ixx="1.11576993679738E-06" ixy="-4.21493357126095E-14" ixz="1.40217613791255E-12" iyy="1.10112215482059E-06" iyz="1.07383854570091E-07" izz="2.80496245620477E-07" />
    </inertial>
    <visual>
      <origin xyz="0 0 0" rpy="0 0 0" />
      <geometry>
        <mesh filename="./aero_hand_meshes/right_pinky_proximal_link.STL" />
      </geometry>
      <material name="aero_hand_gray">
        <color rgba="0.7 0.7 0.7 1" />
      </material>
    </visual>
    <collision>
      <origin xyz="0 0 0" rpy="0 0 0" />
      <geometry>
        <mesh filename="./aero_hand_meshes/right_pinky_proximal_link.STL" />
      </geometry>
    </collision>
  </link>
  <joint name="right_pinky_mcp_flex" type="revolute">
    <origin xyz="-0.038266 -0.0036416 0.092393" rpy="0 -0.10472 0.069946" />
    <parent link="right_base_link" />
    <child link="right_pinky_proximal_link" />
    <axis xyz="1 0 0" />
    <limit lower="0" upper="1.5708" effort="0" velocity="0" />
  </joint>
  <link name="right_pinky_middle_link">
    <inertial>
      <origin xyz="-7.30330518283751E-09 -0.000363268490759203 0.00876078540200605" rpy="0 0 0" />
      <mass value="0.00276150617991104" />
      <inertia ixx="1.80417146629369E-07" ixy="2.77370887761691E-13" ixz="-2.37462864018002E-13" iyy="1.98972592220503E-07" iyz="7.65598318320784E-09" izz="8.9335305249386E-08" />
    </inertial>
    <visual>
      <origin xyz="0 0 0" rpy="0 0 0" />
      <geometry>
        <mesh filename="./aero_hand_meshes/right_pinky_middle_link.STL" />
      </geometry>
      <material name="aero_hand_gray">
        <color rgba="0.7 0.7 0.7 1" />
      </material>
    </visual>
    <collision>
      <origin xyz="0 0 0" rpy="0 0 0" />
      <geometry>
        <mesh filename="./aero_hand_meshes/right_pinky_middle_link.STL" />
      </geometry>
    </collision>
  </link>
  <joint name="right_pinky_pip" type="revolute">
    <origin xyz="0 -0.0014554 0.043" rpy="0 0 0" />
    <parent link="right_pinky_proximal_link" />
    <child link="right_pinky_middle_link" />
    <axis xyz="1 0 0" />
    <limit lower="0" upper="1.5708" effort="0" velocity="0" />
  </joint>
  <link name="right_pinky_distal_link">
    <inertial>
      <origin xyz="4.31454935043152E-07 -0.00120202346438717 0.00777263499391853" rpy="0 0 0" />
      <mass value="0.00183662951045839" />
      <inertia ixx="1.08241793280288E-07" ixy="3.02667643229166E-12" ixz="-1.26562320795476E-13" iyy="1.00245694664433E-07" iyz="-1.85886254587434E-08" izz="3.57206185143609E-08" />
    </inertial>
    <visual>
      <origin xyz="0 0 0" rpy="0 0 0" />
      <geometry>
        <mesh filename="./aero_hand_meshes/right_pinky_distal_link.STL" />
      </geometry>
      <material name="aero_hand_gray">
        <color rgba="0.7 0.7 0.7 1" />
      </material>
    </visual>
    <collision>
      <origin xyz="0 0 0" rpy="0 0 0" />
      <geometry>
        <mesh filename="./aero_hand_meshes/right_pinky_distal_link.STL" />
      </geometry>
    </collision>
    <visual>
      <origin xyz="0 0.003512 0.026776" rpy="0 0 0" />
      <geometry>
        <mesh filename="./aero_hand_meshes/right_pinky_tip_link.STL" />
      </geometry>
      <material name="aero_hand_gray">
        <color rgba="0.7 0.7 0.7 1" />
      </material>
    </visual>
    <collision>
      <origin xyz="0 0.003512 0.026776" rpy="0 0 0" />
      <geometry>
        <mesh filename="./aero_hand_meshes/right_pinky_tip_link.STL" />
      </geometry>
    </collision>
  </link>
  <joint name="right_pinky_dip" type="revolute">
    <origin xyz="0 0 0.022" rpy="0 0 0" />
    <parent link="right_pinky_middle_link" />
    <child link="right_pinky_distal_link" />
    <axis xyz="1 0 0" />
    <limit lower="0" upper="1.5708" effort="0" velocity="0" />
  </joint>
</robot>